<?xml version="1.0" ?>
<!-- =================================================================================== -->
<!-- |    This document was autogenerated by xacro from jueying_black_correct.urdf     | -->
<!-- |    EDITING THIS FILE BY HAND IS NOT RECOMMENDED                                 | -->
<!-- =================================================================================== -->


<robot name="mini" xmlns:xacro="http://www.ros.org/wiki/xacro">
  <material name="grey">
    <color rgba="0.4 0.4 0.4 1.0"/>
  </material>

  <link name="origin_link">
    <inertial>
      <mass value="1e-5"/>
      <origin rpy="0 0 0" xyz="0 0 0"/>
      <inertia ixx="0" ixy="0" ixz="0" iyy="0" iyz="0" izz="0"/>
    </inertial>
    <collision>
      <geometry>
        <box size="0.02 0.02 0.02"/> 
        <!-- <box size="0.67 0.23 0.29"/> -->
      </geometry>
      <origin rpy="0.0 0.0 0.0" xyz="0.0 0.0 0.0"/>
    </collision>
  </link>
  <joint name="origin_baselink_joint" type="fixed">
    <origin rpy="0 0 0" xyz="0 0 0.0"/>
    <parent link="origin_link"/>
    <child link="base_link"/>
  </joint>
  <!--
  <link name="imu_link">
    <inertial>
      <mass value="0.001"/>
      <origin rpy="0 0 0" xyz="0 0 0"/>
      <inertia ixx="0.0001" ixy="0" ixz="0" iyy="0.000001" iyz="0" izz="0.0001"/>
    </inertial>
    <visual>
      <origin rpy="0 0 0" xyz="0 0 0"/>
      <geometry>
        <box size="0.001 0.001 0.001"/>
      </geometry>
    </visual>
    <collision>
      <origin rpy="0 0 0" xyz="0 0 0"/>
      <geometry>
        <box size=".001 .001 .001"/>
      </geometry>
    </collision>
  </link>
  <joint name="imu_joint" type="fixed">
    <axis xyz="0 0 0"/>
    <origin xyz="0 0 0"/>
    <parent link="base_link"/>
    <child link="imu_link"/>
  </joint>
  -->

  <link name="base_link">
    <inertial>
      <origin rpy="0 0 0" xyz="0.062025 -0.00020608 0.036811"/>
      <mass value="22"/>
      <inertia ixx="0.030916" ixy="-0.00015304" ixz="-0.019048" iyy="0.24659" iyz="-1.0144E-05" izz="0.23908"/>
    </inertial>
    <visual>
      <origin rpy="0 0 0" xyz="0 0 0"/>
      <geometry>
        <mesh filename="../meshes/base_link.obj"/>
      </geometry>
      <material name="grey"/>
    </visual>
    <collision>
      <origin rpy="0 0 0" xyz="0 0 0"/>
      <geometry>
        <!-- <mesh filename="../meshes/base_link.obj"/> -->
        <box size="0.66 0.22 0.28"/>
      </geometry>
    </collision>
  </link>



  <link name="FL_HipX">
    <inertial>
      <origin rpy="0 0 0" xyz="-0.008972 0.0034481 -0.00046845"/>
      <mass value="1.7"/>
      <inertia ixx="0.00019667" ixy="-4.8374E-06" ixz="6.5367E-07" iyy="0.0002677" iyz="1.8987E-06" izz="0.00025573"/>
    </inertial>
    <visual>
      <origin rpy="0 0 0" xyz="0 0 0"/>
      <geometry>
        <mesh filename="../meshes/FL_HipX.obj"/>
      </geometry>
      <material name="grey"/>
    </visual>
    <collision>
      <!-- <origin rpy="0 0 0" xyz="0 0 0"/> -->
      <origin rpy="1.57079632679 0 0" xyz="0 0.021 0"/>
      <geometry>
        <!-- <mesh filename="../meshes/FL_HipX.obj"/> -->
        <cylinder length="0.11" radius="0.07"/>
      </geometry>
    </collision>
  </link>
  <joint name="FL_hip_motor_2_chassis_joint" type="revolute">
    <origin rpy="0 0 0" xyz="0.295 0.0625 0"/>
    <parent link="origin_link"/>
    <child link="FL_HipX"/>
    <axis xyz="-1 0 0"/>
    <limit effort="25" lower="-0.5236" upper="0.5236" velocity="18"/>
    <dynamics damping="1.2" friction="0.2"/>
  </joint>

  <joint name="FL_hip_fixed" type="fixed">
    <origin rpy="0 0 0" xyz="0 0.1 0"/>
    <parent link="FL_HipX"/>
    <child link="FL_thigh_shoulder"/>
  </joint>
  <!-- this link is only for collision -->
  <link name="FL_thigh_shoulder">
    <collision>
      <origin rpy="1.57079632679 0 0" xyz="0 0.0 0"/>
      <geometry>
        <cylinder length="0.115" radius="0.075"/>
      </geometry>
    </collision>
  </link>

  <link name="FL_HipY">
    <inertial>
      <origin rpy="0 0 0" xyz="-0.0087166 0.017938 -0.090687"/>
      <mass value="3"/>
      <inertia ixx="0.009502" ixy="-0.00013152" ixz="-0.00045866" iyy="0.0094286" iyz="-0.0010116" izz="0.001321"/>
    </inertial>
    <visual>
      <origin rpy="0 0 0" xyz="0 0 0"/>
      <geometry>
        <mesh filename="../meshes/FL_HipY.obj"/>
      </geometry>
      <material name="grey"/>
    </visual>
    <collision>
      <origin rpy="0 1.57079632679 0" xyz="0 0 -0.125"/>
      <!-- <origin rpy="1.57079632679 0 0" xyz="-0.0087166 0.017938 0"/> -->
      <geometry>
        <!-- <mesh filename="../meshes/FL_HipY.obj"/> -->
        <!-- <cylinder length="0.11" radius="0.07"/> -->
        <box size="0.25 0.034 0.043"/>
      </geometry>
    </collision>
  </link>
  <joint name="FL_upper_leg_2_hip_motor_joint" type="revolute">
    <origin rpy="0 0 0" xyz="0 0.088 0"/>
    <parent link="FL_HipX"/>
    <child link="FL_HipY"/>
    <axis xyz="0 -1 0"/>
    <limit effort="25" lower="-2.7925" upper="0.3491" velocity="18"/>
    <dynamics damping="1.2" friction="0.2"/>
  </joint>

  <link name="FL_Knee">
    <inertial>
      <origin rpy="0 0 0" xyz="0.0041187 -2.5016E-07 -0.14755"/>
      <mass value="0.3"/>
      <inertia ixx="0.0054815" ixy="1.545E-10" ixz="9.7849E-05" iyy="0.0055465" iyz="7.5423E-09" izz="0.00010377"/>
    </inertial>
    <visual>
      <origin rpy="0 0 0" xyz="0 0 0"/>
      <geometry>
        <mesh filename="../meshes/FL_Knee.obj"/>
      </geometry>
      <material name="grey"/>
    </visual>
    <collision>
      <!-- <origin rpy="0 0 0" xyz="0 0 0"/> -->
      <origin rpy="0 1.57079632679 0" xyz="0 0 -0.125"/>
      <geometry>
        <!-- <mesh filename="../meshes/FL_Knee.obj"/> -->
        <box size="0.25 0.016 0.036"/>
      </geometry>
    </collision>
  </link>
  <joint name="FL_lower_leg_2_upper_leg_joint" type="revolute">
    <origin rpy="0 0 0" xyz="0 0 -0.33"/>
    <parent link="FL_HipY"/>
    <child link="FL_Knee"/>
    <axis xyz="0 -1 0"/>
    <limit effort="45" lower="0.6981" upper="2.7925" velocity="18"/>
    <dynamics damping="1.2" friction="0.2"/>
  </joint>

  <link name="FL_foot">
  <contact>
      <lateral_friction value="1"/>
  </contact>
    <inertial>
      <origin rpy="0 0 0" xyz="0 -0 0"/>
       <mass value="1e-5"/>
       <inertia ixx="0" ixy="0" ixz="0" iyy="0" iyz="0" izz="0"/>
    </inertial>
    <visual>
      <origin rpy="0 0 0" xyz="0 0.0 0"/>
      <geometry>
        <cylinder length="0.045" radius="0.045"/>
      </geometry>
      <!-- <material name="grey"/> -->
    </visual>
    <collision>
      <origin rpy="0 0 0" xyz="0 0.0 0"/>
      <geometry>
        <cylinder length="0.045" radius="0.045"/>
      </geometry>
    </collision>
  </link>
  <joint name="FL_lower_leg_2_foot_joint" type="fixed">
    <axis xyz="0 0 0"/>
	  <parent link="FL_Knee"/>
      <child link="FL_foot"/>
	  <origin rpy="1.57 0 0" xyz="0.0 0  -0.335"/>
  </joint>



  <link name="FR_HipX">
    <inertial>
      <origin rpy="0 0 0" xyz="-0.008972 -0.0034481 0.00046845"/>
      <mass value="1.7"/>
      <inertia ixx="0.00019667" ixy="4.8374E-06" ixz="-6.5367E-07" iyy="0.0002677" iyz="1.8987E-06" izz="0.00025573"/>
    </inertial>
    <visual>
      <origin rpy="0 0 0" xyz="0 0 0"/>
      <geometry>
        <mesh filename="../meshes/FR_HipX.obj"/>
      </geometry>
      <material name="grey"/>
    </visual>
    <collision>
      <!-- <origin rpy="0 0 0" xyz="0 0 0"/> -->
      <origin rpy="1.57079632679 0 0" xyz="0 -0.021 0"/>
      <geometry>
        <!-- <mesh filename="../meshes/FR_HipX.obj"/> -->
        <cylinder length="0.11" radius="0.07"/>
      </geometry>
    </collision>
  </link>
  <joint name="FR_hip_motor_2_chassis_joint" type="revolute">
    <origin rpy="0 0 0" xyz="0.295 -0.0625 0"/>
    <parent link="origin_link"/>
    <child link="FR_HipX"/>
    <axis xyz="-1 0 0"/>
    <limit effort="25" lower="-0.5236" upper="0.5236" velocity="18"/>
    <dynamics damping="1.2" friction="0.2"/>
  </joint>

  <joint name="FR_hip_fixed" type="fixed">
    <origin rpy="0 0 0" xyz="0 -0.1 0"/>
    <parent link="FR_HipX"/>
    <child link="FR_thigh_shoulder"/>
  </joint>
  <!-- this link is only for collision -->
  <link name="FR_thigh_shoulder">
    <collision>
      <origin rpy="1.57079632679 0 0" xyz="0 0.0 0"/>
      <geometry>
        <cylinder length="0.115" radius="0.075"/>
      </geometry>
    </collision>
  </link>

  <link name="FR_HipY">
    <inertial>
      <origin rpy="0 0 0" xyz="-0.0087151 -0.017939 -0.090687"/>
      <mass value="3"/>
      <inertia ixx="0.0095019" ixy="0.00013148" ixz="-0.00045867" iyy="0.0094286" iyz="0.0010116" izz="0.0013209"/>
    </inertial>
    <visual>
      <origin rpy="0 0 0" xyz="0 0 0"/>
      <geometry>
        <mesh filename="../meshes/FR_HipY.obj"/>
      </geometry>
      <material name="grey"/>
    </visual>
    <collision>
      <origin rpy="0 1.57079632679 0" xyz="0 0 -0.125"/>
      <geometry>
        <!-- <mesh filename="../meshes/FR_HipY.obj"/> -->
        <box size="0.25 0.034 0.043"/>
      </geometry>
    </collision>
  </link>
  <joint name="FR_upper_leg_2_hip_motor_joint" type="revolute">
    <origin rpy="0 0 0" xyz="0 -0.088 0"/>
    <parent link="FR_HipX"/>
    <child link="FR_HipY"/>
    <axis xyz="0 -1 0"/>
    <limit effort="25" lower="-2.7925" upper="0.3491" velocity="18"/>
    <dynamics damping="1.2" friction="0.2"/>
  </joint>

  <link name="FR_Knee">
    <inertial>
      <origin rpy="0 0 0" xyz="0.0041187 -2.5016E-07 -0.14755"/>
      <mass value="0.3"/>
      <inertia ixx="0.0054815" ixy="1.545E-10" ixz="9.7849E-05" iyy="0.0055465" iyz="7.5424E-09" izz="0.00010377"/>
    </inertial>
    <visual>
      <origin rpy="0 0 0" xyz="0 0 0"/>
      <geometry>
        <mesh filename="../meshes/FR_Knee.obj"/>
      </geometry>
      <material name="grey"/>
    </visual>
    <collision>
      <!-- <origin rpy="0 0 0" xyz="0 0 0"/> -->
      <origin rpy="0 1.57079632679 0" xyz="0 0 -0.125"/>
      <geometry>
        <!-- <mesh filename="../meshes/FR_Knee.obj"/> -->
        <box size="0.25 0.016 0.036"/>
      </geometry>
    </collision>
  </link>
  <joint name="FR_lower_leg_2_upper_leg_joint" type="revolute">
    <origin rpy="0 0 0" xyz="0 0 -0.33"/>
    <parent link="FR_HipY"/>
    <child link="FR_Knee"/>
    <axis xyz="0 -1 0"/>
    <limit effort="45" lower="0.6981" upper="2.7925" velocity="18"/>
    <dynamics damping="1.2" friction="0.2"/>
  </joint>

  <link name="FR_foot">
  <contact>
      <lateral_friction value="1"/>
  </contact>
    <inertial>
      <origin rpy="0 0 0" xyz="0 -0 0"/>
       <mass value="1e-5"/>
       <inertia ixx="0" ixy="0" ixz="0" iyy="0" iyz="0" izz="0"/>
    </inertial>
    <visual>
      <origin rpy="0 0 0" xyz="0 0.0 0"/>
      <geometry>
        <cylinder length="0.045" radius="0.045"/>
      </geometry>
      <!-- <material name="grey"/> -->
    </visual>
    <collision>
      <origin rpy="0 0 0" xyz="0 0.0 0"/>
      <geometry>
        <cylinder length="0.045" radius="0.045"/>
      </geometry>
    </collision>
  </link>
  <joint name="FR_lower_leg_2_foot_joint" type="fixed">
    <axis xyz="0 0 0"/>
	  <parent link="FR_Knee"/>
      <child link="FR_foot"/>
	  <!-- <origin rpy="1.57 0 0" xyz="0.0 0  -0.335"/> -->
	  <origin rpy="1.57 0 0" xyz="0.0 0  -0.335"/>
  </joint>





  <link name="HL_HipX">
    <inertial>
      <origin rpy="0 0 0" xyz="0 0 0"/>
      <mass value="1.7"/>
      <inertia ixx="0" ixy="0" ixz="0" iyy="0" iyz="0" izz="0"/>
    </inertial>
    <visual>
      <origin rpy="0 0 0" xyz="0 0 0"/>
      <geometry>
        <mesh filename="../meshes/HL_HipX.obj"/>
      </geometry>
      <material name="grey"/>
    </visual>
    <collision>
      <!-- <origin rpy="0 0 0" xyz="0 0 0"/> -> -->
      <origin rpy="1.57079632679 0 0" xyz="0 0.021 0"/>
      <geometry>
        <!-- <mesh filename="../meshes/HL_HipX.obj"/> -->
        <cylinder length="0.11" radius="0.07"/>
      </geometry>
    </collision>
  </link>
  <joint name="RL_hip_motor_2_chassis_joint" type="revolute">
    <origin rpy="0 0 0" xyz="-0.295 0.0625 0"/>
    <parent link="origin_link"/>
    <child link="HL_HipX"/>
    <axis xyz="-1 0 0"/>
    <limit effort="25" lower="-0.5236" upper="0.5236" velocity="18"/>
    <dynamics damping="1.2" friction="0.2"/>
  </joint>

  <joint name="HL_hip_fixed" type="fixed">
    <origin rpy="0 0 0" xyz="0 0.1 0"/>
    <parent link="HL_HipX"/>
    <child link="HL_thigh_shoulder"/>
  </joint>
  <!-- this link is only for collision -->
  <link name="HL_thigh_shoulder">
    <collision>
      <origin rpy="1.57079632679 0 0" xyz="0 0.0 0"/>
      <geometry>
        <cylinder length="0.115" radius="0.075"/>
      </geometry>
    </collision>
  </link>

  <link name="HL_HipY">
    <inertial>
      <origin rpy="0 0 0" xyz="-0.0087166 0.017938 -0.090687"/>
      <mass value="3"/>
      <inertia ixx="0.009502" ixy="-0.00013152" ixz="-0.00045866" iyy="0.0094286" iyz="-0.0010116" izz="0.001321"/>
    </inertial>
    <visual>
      <origin rpy="0 0 0" xyz="0 0 0"/>
      <geometry>
        <mesh filename="../meshes/HL_HipY.obj"/>
      </geometry>
      <material name="grey"/>
    </visual>
    <collision>
      <!-- <origin rpy="0 0 0" xyz="0 0 0"/> -->
      <origin rpy="0 1.57079632679 0" xyz="0 0 -0.125"/>
      <geometry>
        <!-- <mesh filename="../meshes/HL_HipY.obj"/> -->
        <box size="0.25 0.034 0.043"/>
      </geometry>
    </collision>
  </link>
  <joint name="RL_upper_leg_2_hip_motor_joint" type="revolute">
    <origin rpy="0 0 0" xyz="0 0.088 0"/>
    <parent link="HL_HipX"/>
    <child link="HL_HipY"/>
    <axis xyz="0 -1 0"/>
    <limit effort="25" lower="-2.7925" upper="0.2491" velocity="18"/>
    <dynamics damping="1.2" friction="0.2"/>
  </joint>

  <link name="HL_Knee">
    <inertial>
      <origin rpy="0 0 0" xyz="0.0041187 -2.5016E-07 -0.14755"/>
      <mass value="0.3"/>
      <inertia ixx="0.0054815" ixy="1.545E-10" ixz="9.7849E-05" iyy="0.0055465" iyz="7.5424E-09" izz="0.00010377"/>
    </inertial>
    <visual>
      <origin rpy="0 0 0" xyz="0 0 0"/>
      <geometry>
        <mesh filename="../meshes/HL_Knee.obj"/>
      </geometry>
      <material name="grey"/>
    </visual>
    <collision>
      <!-- <origin rpy="0 0 0" xyz="0 0 0"/> -->
      <origin rpy="0 1.57079632679 0" xyz="0 0 -0.125"/>
      <geometry>
        <!-- <mesh filename="../meshes/HL_Knee.obj"/> -->
        <box size="0.25 0.016 0.036"/>
      </geometry>
    </collision>
  </link>
  <joint name="RL_lower_leg_2_upper_leg_joint" type="revolute">
    <origin rpy="0 0 0" xyz="0 0 -0.33"/>
    <parent link="HL_HipY"/>
    <child link="HL_Knee"/>
    <axis xyz="0 -1 0"/>
    <limit effort="45" lower="0.6981" upper="2.7925" velocity="18"/>
    <dynamics damping="1.2" friction="0.2"/>
  </joint>

  <link name="HL_foot">
  <contact>
      <lateral_friction value="1"/>
  </contact>
    <inertial>
      <origin rpy="0 0 0" xyz="0 -0 0"/>
       <mass value="1e-5"/>
       <inertia ixx="0" ixy="0" ixz="0" iyy="0" iyz="0" izz="0"/>
    </inertial>
    <visual>
      <origin rpy="0 0 0" xyz="0 0.0 0"/>
      <geometry>
        <cylinder length="0.045" radius="0.045"/>
      </geometry>
      <!-- <material name="grey"/> -->
    </visual>
    <collision>
      <origin rpy="0 0 0" xyz="0 0.0 0"/>
      <geometry>
        <cylinder length="0.045" radius="0.045"/>
      </geometry>
    </collision>
  </link>
  <joint name="RL_lower_leg_2_foot_joint" type="fixed">
    <axis xyz="0 0 0"/>
	  <parent link="HL_Knee"/>
      <child link="HL_foot"/>
	  <origin rpy="1.57 0 0" xyz="0.0 0  -0.335"/>
  </joint>

  <link name="HR_HipX">
    <inertial>
      <origin rpy="0 0 0" xyz="0.008972 -0.0034481 -0.00046845"/>
      <mass value="1.7"/>
      <inertia ixx="0.00019667" ixy="-4.8374E-06" ixz="-6.5367E-07" iyy="0.0002677" iyz="-1.8987E-06" izz="0.00025573"/>
    </inertial>
    <visual>
      <origin rpy="0 0 0" xyz="0 0 0"/>
      <geometry>
        <mesh filename="../meshes/HR_HipX.obj"/>
      </geometry>
      <material name="grey"/>
    </visual>
    <collision>
      <!-- <origin rpy="0 0 0" xyz="0 0 0"/> -->
      <origin rpy="1.57079632679 0 0" xyz="0 -0.021 0"/>
      <geometry>
        <!-- <mesh filename="../meshes/HR_HipX.obj"/> -->
        <cylinder length="0.11" radius="0.07"/>
      </geometry>
    </collision>
  </link>
  <joint name="RR_hip_motor_2_chassis_joint" type="revolute">
    <origin rpy="0 0 0" xyz="-0.295 -0.0625 0"/>
    <parent link="origin_link"/>
    <child link="HR_HipX"/>
    <axis xyz="-1 0 0"/>
    <limit effort="25" lower="-0.5236" upper="0.5236" velocity="18"/>
    <dynamics damping="1.2" friction="0.2"/>
  </joint>

  <joint name="HR_hip_fixed" type="fixed">
    <origin rpy="0 0 0" xyz="0 -0.1 0"/>
    <parent link="HR_HipX"/>
    <child link="HR_thigh_shoulder"/>
  </joint>
  <!-- this link is only for collision -->
  <link name="HR_thigh_shoulder">
    <collision>
      <origin rpy="1.57079632679 0 0" xyz="0 0.0 0"/>
      <geometry>
        <cylinder length="0.115" radius="0.075"/>
      </geometry>
    </collision>
  </link>

  <link name="HR_HipY">
    <inertial>
      <origin rpy="0 0 0" xyz="-0.0087151 -0.017939 -0.090687"/>
      <mass value="3"/>
      <inertia ixx="0.0095019" ixy="0.00013148" ixz="-0.00045867" iyy="0.0094286" iyz="0.0010116" izz="0.0013209"/>
    </inertial>
    <visual>
      <origin rpy="0 0 0" xyz="0 0 0"/>
      <geometry>
        <mesh filename="../meshes/HR_HipY.obj"/>
      </geometry>
      <material name="grey"/>
    </visual>
    <collision>
      <!-- <origin rpy="0 0 0" xyz="0 0 0"/> -->
      <origin rpy="0 1.57079632679 0" xyz="0 0 -0.125"/>
      <geometry>
        <!-- <mesh filename="../meshes/HR_HipY.obj"/> -->
        <box size="0.25 0.034 0.043"/>
      </geometry>
    </collision>
  </link>
  <joint name="RR_upper_leg_2_hip_motor_joint" type="revolute">
    <origin rpy="0 0 0" xyz="0 -0.088 0"/>
    <parent link="HR_HipX"/>
    <child link="HR_HipY"/>
    <axis xyz="0 -1 0"/>
    <limit effort="25" lower="-2.7925" upper="0.3491" velocity="18"/>
    <dynamics damping="1.2" friction="0.2"/>
  </joint>

  <link name="HR_Knee">
    <inertial>
      <origin rpy="0 0 0" xyz="0.0041187 -2.5016E-07 -0.14755"/>
      <mass value="0.3"/>
      <inertia ixx="0.0054815" ixy="1.5451E-10" ixz="9.7849E-05" iyy="0.0055465" iyz="7.5424E-09" izz="0.00010377"/>
    </inertial>
    <visual>
      <origin rpy="0 0 0" xyz="0 0 0"/>
      <geometry>
        <mesh filename="../meshes/HR_Knee.obj"/>
      </geometry>
      <material name="grey"/>
    </visual>
    <collision>
      <!-- <origin rpy="0 0 0" xyz="0 0 0"/> -->
      <origin rpy="0 1.57079632679 0" xyz="0 0 -0.125"/>
      <geometry>
        <!-- <mesh filename="../meshes/HR_Knee.obj"/> -->
        <box size="0.25 0.016 0.036"/>
      </geometry>
    </collision>
  </link>
  <joint name="RR_lower_leg_2_upper_leg_joint" type="revolute">
    <origin rpy="0 0 0" xyz="0 0 -0.33"/>
    <parent link="HR_HipY"/>
    <child link="HR_Knee"/>
    <axis xyz="0 -1 0"/>
    <limit effort="45" lower="0.6981" upper="2.7925" velocity="18"/>
    <dynamics damping="1.2" friction="0.2"/>
  </joint>

  <link name="HR_foot">
  <contact>
      <lateral_friction value="1"/>
  </contact>
    <inertial>
      <origin rpy="0 0 0" xyz="0 -0 0"/>
       <mass value="1e-5"/>
       <inertia ixx="0" ixy="0" ixz="0" iyy="0" iyz="0" izz="0"/>
    </inertial>
    <visual>
      <origin rpy="0 0 0" xyz="0 0.0 0"/>
      <geometry>
        <cylinder length="0.045" radius="0.045"/>
      </geometry>
      <!-- <material name="grey"/> -->
    </visual>
    <collision>
      <origin rpy="0 0 0" xyz="0 0.0 0"/>
      <geometry>
        <cylinder length="0.045" radius="0.045"/>
      </geometry>
    </collision>
  </link>
  <joint name="RR_lower_leg_2_foot_joint" type="fixed">
    <axis xyz="0 0 0"/>
	  <parent link="HR_Knee"/>
      <child link="HR_foot"/>
	  <origin rpy="1.57 0 0" xyz="0.0 0  -0.335"/>
  </joint>

</robot>
